INFO:root:Executed R('load(\'hw2/ex4-tests.rda\')')
INFO:root:Executed R('test.gg.output <- testGroupsGestation(test.data, g1, g2, test.alternative="greater")$p.value')
ERROR:root:(1 points) Checking R('all.equal(test.groups.gestation.t$p.value, test.gg.output, tolerance=1e-5)')[0]
ERROR:root:... Expecting: True
ERROR:root:... But got:   Modes: numeric, NULL
INFO:root:Executed R('load(\'hw3/ex2-tests.rda\')')
INFO:root:(1 points) R('all.equal(col.sorter.t, colSorter(ex2.test1))')[0] is True
INFO:root:(1 points) R('all.equal(row.sorter.t, rowSorter(ex2.test2))')[0] is True
INFO:root:(2 points) R('all.equal(unname(unlist(factor.sorter.t)), unname(unlist(factorSorter(iris, \'Sepal.Length\'))))')[0] is True
INFO:root:Executed R('load(\'hw3/ex3-tests.rda\')')
INFO:root:(1 points) R('all.equal(sum.na.t, sumNA(ex3.test1))')[0] is True
INFO:root:Executed R('set.seed(47)')
INFO:root:(1 points) R('all.equal(simulate.normals.t, simulateNormals(100, 5, 4, 5))')[0] is True
INFO:root:(1 points) R('all.equal(list.lengths.t, listLengths(ex3.test2))')[0] is True
ERROR:root:(1 points) Checking R('all.equal(matrix.list.means.t, matrixListMeans(ex3.test3))')[0]
ERROR:root:... Expecting: True
ERROR:root:... But got:   Traceback error
ERROR:root:Got exception:
Traceback (most recent call last):
  File "/Users/Karl/anaconda/lib/python2.7/site-packages/gradebook/score.py", line 180, in check
    result = eval(command, g)
  File "<string>", line 1, in <module>
  File "/Users/Karl/anaconda/lib/python2.7/site-packages/rpy2/robjects/__init__.py", line 248, in __call__
    res = self.eval(p)
  File "/Users/Karl/anaconda/lib/python2.7/site-packages/rpy2/robjects/functions.py", line 166, in __call__
    return super(SignatureTranslatedFunction, self).__call__(*args, **kwargs)
  File "/Users/Karl/anaconda/lib/python2.7/site-packages/rpy2/robjects/functions.py", line 99, in __call__
    res = super(Function, self).__call__(*new_args, **new_kwargs)
RRuntimeError: Error in FUN(X[[1L]], ...) : 
  'x' must be an array of at least two dimensions

ERROR:root:Traceback (most recent call last):
  File "/Users/Karl/anaconda/lib/python2.7/site-packages/gradebook/score.py", line 180, in check
    result = eval(command, g)
  File "<string>", line 1, in <module>
  File "/Users/Karl/anaconda/lib/python2.7/site-packages/rpy2/robjects/__init__.py", line 248, in __call__
    res = self.eval(p)
  File "/Users/Karl/anaconda/lib/python2.7/site-packages/rpy2/robjects/functions.py", line 166, in __call__
    return super(SignatureTranslatedFunction, self).__call__(*args, **kwargs)
  File "/Users/Karl/anaconda/lib/python2.7/site-packages/rpy2/robjects/functions.py", line 99, in __call__
    res = super(Function, self).__call__(*new_args, **new_kwargs)
RRuntimeError: Error in FUN(X[[1L]], ...) : 
  'x' must be an array of at least two dimensions

Traceback (most recent call last):
  File "/Users/Karl/anaconda/lib/python2.7/site-packages/gradebook/score.py", line 180, in check
    result = eval(command, g)
  File "<string>", line 1, in <module>
  File "/Users/Karl/anaconda/lib/python2.7/site-packages/rpy2/robjects/__init__.py", line 248, in __call__
    res = self.eval(p)
  File "/Users/Karl/anaconda/lib/python2.7/site-packages/rpy2/robjects/functions.py", line 166, in __call__
    return super(SignatureTranslatedFunction, self).__call__(*args, **kwargs)
  File "/Users/Karl/anaconda/lib/python2.7/site-packages/rpy2/robjects/functions.py", line 99, in __call__
    res = super(Function, self).__call__(*new_args, **new_kwargs)
RRuntimeError: Error in FUN(X[[1L]], ...) : 
  'x' must be an array of at least two dimensions

ERROR:root:(1 points) Checking R('all.equal(stand.matrix.variables.t, standMatrixVariables(ex3.test4))')[0]
ERROR:root:... Expecting: True
ERROR:root:... But got:   Traceback error
ERROR:root:Got exception:
Traceback (most recent call last):
  File "/Users/Karl/anaconda/lib/python2.7/site-packages/gradebook/score.py", line 180, in check
    result = eval(command, g)
  File "<string>", line 1, in <module>
  File "/Users/Karl/anaconda/lib/python2.7/site-packages/rpy2/robjects/__init__.py", line 248, in __call__
    res = self.eval(p)
  File "/Users/Karl/anaconda/lib/python2.7/site-packages/rpy2/robjects/functions.py", line 166, in __call__
    return super(SignatureTranslatedFunction, self).__call__(*args, **kwargs)
  File "/Users/Karl/anaconda/lib/python2.7/site-packages/rpy2/robjects/functions.py", line 99, in __call__
    res = super(Function, self).__call__(*new_args, **new_kwargs)
RRuntimeError: Error in outer(rows, cols, FUN = fun) : 
  dims [product 25] do not match the length of object [1]

ERROR:root:Traceback (most recent call last):
  File "/Users/Karl/anaconda/lib/python2.7/site-packages/gradebook/score.py", line 180, in check
    result = eval(command, g)
  File "<string>", line 1, in <module>
  File "/Users/Karl/anaconda/lib/python2.7/site-packages/rpy2/robjects/__init__.py", line 248, in __call__
    res = self.eval(p)
  File "/Users/Karl/anaconda/lib/python2.7/site-packages/rpy2/robjects/functions.py", line 166, in __call__
    return super(SignatureTranslatedFunction, self).__call__(*args, **kwargs)
  File "/Users/Karl/anaconda/lib/python2.7/site-packages/rpy2/robjects/functions.py", line 99, in __call__
    res = super(Function, self).__call__(*new_args, **new_kwargs)
RRuntimeError: Error in outer(rows, cols, FUN = fun) : 
  dims [product 25] do not match the length of object [1]

Traceback (most recent call last):
  File "/Users/Karl/anaconda/lib/python2.7/site-packages/gradebook/score.py", line 180, in check
    result = eval(command, g)
  File "<string>", line 1, in <module>
  File "/Users/Karl/anaconda/lib/python2.7/site-packages/rpy2/robjects/__init__.py", line 248, in __call__
    res = self.eval(p)
  File "/Users/Karl/anaconda/lib/python2.7/site-packages/rpy2/robjects/functions.py", line 166, in __call__
    return super(SignatureTranslatedFunction, self).__call__(*args, **kwargs)
  File "/Users/Karl/anaconda/lib/python2.7/site-packages/rpy2/robjects/functions.py", line 99, in __call__
    res = super(Function, self).__call__(*new_args, **new_kwargs)
RRuntimeError: Error in outer(rows, cols, FUN = fun) : 
  dims [product 25] do not match the length of object [1]

INFO:root:You got a 11 out of 30.
